[2021-04-09 09:17:54 +0000] [2517] [INFO] Starting gunicorn 20.1.0
[2021-04-09 09:17:54 +0000] [2517] [INFO] Listening at: http://0.0.0.0:80 (2517)
[2021-04-09 09:17:54 +0000] [2517] [INFO] Using worker: sync
[2021-04-09 09:17:54 +0000] [2521] [INFO] Booting worker with pid: 2521
[2021-04-09 09:17:55 +0000] [2521] [ERROR] Exception in worker process
Traceback (most recent call last):
  File "/home/user/.local/lib/python3.6/site-packages/gunicorn/util.py", line 359, in import_app
    mod = importlib.import_module(module)
  File "/usr/lib/python3.6/importlib/__init__.py", line 126, in import_module
    return _bootstrap._gcd_import(name[level:], package, level)
  File "<frozen importlib._bootstrap>", line 994, in _gcd_import
  File "<frozen importlib._bootstrap>", line 971, in _find_and_load
  File "<frozen importlib._bootstrap>", line 950, in _find_and_load_unlocked
ModuleNotFoundError: No module named 'flask_server.py'; 'flask_server' is not a package

During handling of the above exception, another exception occurred:

Traceback (most recent call last):
  File "/home/user/.local/lib/python3.6/site-packages/gunicorn/arbiter.py", line 589, in spawn_worker
    worker.init_process()
  File "/home/user/.local/lib/python3.6/site-packages/gunicorn/workers/base.py", line 134, in init_process
    self.load_wsgi()
  File "/home/user/.local/lib/python3.6/site-packages/gunicorn/workers/base.py", line 146, in load_wsgi
    self.wsgi = self.app.wsgi()
  File "/home/user/.local/lib/python3.6/site-packages/gunicorn/app/base.py", line 67, in wsgi
    self.callable = self.load()
  File "/home/user/.local/lib/python3.6/site-packages/gunicorn/app/wsgiapp.py", line 58, in load
    return self.load_wsgiapp()
  File "/home/user/.local/lib/python3.6/site-packages/gunicorn/app/wsgiapp.py", line 48, in load_wsgiapp
    return util.import_app(self.app_uri)
  File "/home/user/.local/lib/python3.6/site-packages/gunicorn/util.py", line 363, in import_app
    raise ImportError(msg % (module.rsplit(".", 1)[0], obj))
ImportError: Failed to find application, did you mean 'flask_server:app'?
[2021-04-09 09:17:55 +0000] [2521] [INFO] Worker exiting (pid: 2521)
[2021-04-09 09:17:55 +0000] [2517] [INFO] Shutting down: Master
[2021-04-09 09:17:55 +0000] [2517] [INFO] Reason: Worker failed to boot.
[2021-04-09 09:19:26 +0000] [2559] [INFO] Starting gunicorn 20.1.0
[2021-04-09 09:19:26 +0000] [2559] [INFO] Listening at: http://0.0.0.0:80 (2559)
[2021-04-09 09:19:26 +0000] [2559] [INFO] Using worker: sync
[2021-04-09 09:19:26 +0000] [2563] [INFO] Booting worker with pid: 2563
[2021-04-09 09:19:26 +0000] [2563] [ERROR] Exception in worker process
Traceback (most recent call last):
  File "/home/user/.local/lib/python3.6/site-packages/gunicorn/util.py", line 359, in import_app
    mod = importlib.import_module(module)
  File "/usr/lib/python3.6/importlib/__init__.py", line 126, in import_module
    return _bootstrap._gcd_import(name[level:], package, level)
  File "<frozen importlib._bootstrap>", line 994, in _gcd_import
  File "<frozen importlib._bootstrap>", line 971, in _find_and_load
  File "<frozen importlib._bootstrap>", line 950, in _find_and_load_unlocked
ModuleNotFoundError: No module named 'flask_server.py'; 'flask_server' is not a package

During handling of the above exception, another exception occurred:

Traceback (most recent call last):
  File "/home/user/.local/lib/python3.6/site-packages/gunicorn/arbiter.py", line 589, in spawn_worker
    worker.init_process()
  File "/home/user/.local/lib/python3.6/site-packages/gunicorn/workers/base.py", line 134, in init_process
    self.load_wsgi()
  File "/home/user/.local/lib/python3.6/site-packages/gunicorn/workers/base.py", line 146, in load_wsgi
    self.wsgi = self.app.wsgi()
  File "/home/user/.local/lib/python3.6/site-packages/gunicorn/app/base.py", line 67, in wsgi
    self.callable = self.load()
  File "/home/user/.local/lib/python3.6/site-packages/gunicorn/app/wsgiapp.py", line 58, in load
    return self.load_wsgiapp()
  File "/home/user/.local/lib/python3.6/site-packages/gunicorn/app/wsgiapp.py", line 48, in load_wsgiapp
    return util.import_app(self.app_uri)
  File "/home/user/.local/lib/python3.6/site-packages/gunicorn/util.py", line 363, in import_app
    raise ImportError(msg % (module.rsplit(".", 1)[0], obj))
ImportError: Failed to find application, did you mean 'flask_server:app'?
[2021-04-09 09:19:26 +0000] [2563] [INFO] Worker exiting (pid: 2563)
[2021-04-09 09:19:26 +0000] [2559] [INFO] Shutting down: Master
[2021-04-09 09:19:26 +0000] [2559] [INFO] Reason: Worker failed to boot.
[2021-04-09 09:19:57 +0000] [2567] [INFO] Starting gunicorn 20.1.0
[2021-04-09 09:19:57 +0000] [2567] [INFO] Listening at: http://0.0.0.0:80 (2567)
[2021-04-09 09:19:57 +0000] [2567] [INFO] Using worker: sync
[2021-04-09 09:19:57 +0000] [2571] [INFO] Booting worker with pid: 2571
[2021-04-09 09:19:57 +0000] [2571] [ERROR] Exception in worker process
Traceback (most recent call last):
  File "/home/user/.local/lib/python3.6/site-packages/gunicorn/util.py", line 359, in import_app
    mod = importlib.import_module(module)
  File "/usr/lib/python3.6/importlib/__init__.py", line 126, in import_module
    return _bootstrap._gcd_import(name[level:], package, level)
  File "<frozen importlib._bootstrap>", line 994, in _gcd_import
  File "<frozen importlib._bootstrap>", line 971, in _find_and_load
  File "<frozen importlib._bootstrap>", line 950, in _find_and_load_unlocked
ModuleNotFoundError: No module named 'flask_server.py'; 'flask_server' is not a package

During handling of the above exception, another exception occurred:

Traceback (most recent call last):
  File "/home/user/.local/lib/python3.6/site-packages/gunicorn/arbiter.py", line 589, in spawn_worker
    worker.init_process()
  File "/home/user/.local/lib/python3.6/site-packages/gunicorn/workers/base.py", line 134, in init_process
    self.load_wsgi()
  File "/home/user/.local/lib/python3.6/site-packages/gunicorn/workers/base.py", line 146, in load_wsgi
    self.wsgi = self.app.wsgi()
  File "/home/user/.local/lib/python3.6/site-packages/gunicorn/app/base.py", line 67, in wsgi
    self.callable = self.load()
  File "/home/user/.local/lib/python3.6/site-packages/gunicorn/app/wsgiapp.py", line 58, in load
    return self.load_wsgiapp()
  File "/home/user/.local/lib/python3.6/site-packages/gunicorn/app/wsgiapp.py", line 48, in load_wsgiapp
    return util.import_app(self.app_uri)
  File "/home/user/.local/lib/python3.6/site-packages/gunicorn/util.py", line 363, in import_app
    raise ImportError(msg % (module.rsplit(".", 1)[0], obj))
ImportError: Failed to find application, did you mean 'flask_server:app'?
[2021-04-09 09:19:57 +0000] [2571] [INFO] Worker exiting (pid: 2571)
[2021-04-09 09:19:57 +0000] [2567] [INFO] Shutting down: Master
[2021-04-09 09:19:57 +0000] [2567] [INFO] Reason: Worker failed to boot.
[2021-04-09 09:21:42 +0000] [2576] [INFO] Starting gunicorn 20.1.0
[2021-04-09 09:21:42 +0000] [2576] [INFO] Listening at: http://0.0.0.0:80 (2576)
[2021-04-09 09:21:42 +0000] [2576] [INFO] Using worker: sync
[2021-04-09 09:21:42 +0000] [2580] [INFO] Booting worker with pid: 2580
[2021-04-09 09:22:27 +0000] [2576] [INFO] Handling signal: int
[2021-04-09 09:22:27 +0000] [2580] [INFO] Worker exiting (pid: 2580)
[2021-04-09 09:22:27 +0000] [2576] [INFO] Shutting down: Master
[2021-04-09 09:22:39 +0000] [2609] [INFO] Starting gunicorn 20.1.0
[2021-04-09 09:22:39 +0000] [2609] [INFO] Listening at: http://0.0.0.0:80 (2609)
[2021-04-09 09:22:39 +0000] [2609] [INFO] Using worker: sync
[2021-04-09 09:22:39 +0000] [2613] [INFO] Booting worker with pid: 2613
[2021-04-09 09:23:01 +0000] [2609] [INFO] Handling signal: int
[2021-04-09 09:23:01 +0000] [2613] [INFO] Worker exiting (pid: 2613)
[2021-04-09 09:23:02 +0000] [2609] [INFO] Shutting down: Master
[2021-04-09 09:25:26 +0000] [2648] [INFO] Starting gunicorn 20.1.0
[2021-04-09 09:25:26 +0000] [2648] [INFO] Listening at: http://0.0.0.0:80 (2648)
[2021-04-09 09:25:26 +0000] [2648] [INFO] Using worker: sync
[2021-04-09 09:25:26 +0000] [2652] [INFO] Booting worker with pid: 2652
[2021-04-09 09:25:32 +0000] [2648] [INFO] Handling signal: hup
[2021-04-09 09:25:32 +0000] [2648] [INFO] Hang up: Master
[2021-04-09 09:25:32 +0000] [2648] [WARNING] Worker with pid 2652 was terminated due to signal 1
[2021-04-09 09:25:32 +0000] [2654] [INFO] Booting worker with pid: 2654
[2021-04-09 09:25:36,317] ERROR in app: Exception on /track [POST]
Traceback (most recent call last):
  File "/usr/local/lib/python3.6/dist-packages/flask/app.py", line 2447, in wsgi_app
    response = self.full_dispatch_request()
  File "/usr/local/lib/python3.6/dist-packages/flask/app.py", line 1952, in full_dispatch_request
    rv = self.handle_user_exception(e)
  File "/usr/local/lib/python3.6/dist-packages/flask/app.py", line 1821, in handle_user_exception
    reraise(exc_type, exc_value, tb)
  File "/usr/local/lib/python3.6/dist-packages/flask/_compat.py", line 39, in reraise
    raise value
  File "/usr/local/lib/python3.6/dist-packages/flask/app.py", line 1950, in full_dispatch_request
    rv = self.dispatch_request()
  File "/usr/local/lib/python3.6/dist-packages/flask/app.py", line 1936, in dispatch_request
    return self.view_functions[rule.endpoint](**req.view_args)
  File "/home/user/ptz-tracker/flask_server.py", line 41, in tracker_listener
    print("Tracker Successful started on pid: " + str(pid))
OSError: [Errno 5] Input/output error
[2021-04-09 09:26:13 +0000] [2680] [INFO] Starting gunicorn 20.1.0
[2021-04-09 09:26:13 +0000] [2680] [ERROR] Connection in use: ('0.0.0.0', 80)
[2021-04-09 09:26:13 +0000] [2680] [ERROR] Retrying in 1 second.
[2021-04-09 09:26:14 +0000] [2680] [ERROR] Connection in use: ('0.0.0.0', 80)
[2021-04-09 09:26:14 +0000] [2680] [ERROR] Retrying in 1 second.
[2021-04-09 09:26:16 +0000] [2680] [ERROR] Connection in use: ('0.0.0.0', 80)
[2021-04-09 09:26:16 +0000] [2680] [ERROR] Retrying in 1 second.
[2021-04-09 09:26:17 +0000] [2680] [ERROR] Connection in use: ('0.0.0.0', 80)
[2021-04-09 09:26:17 +0000] [2680] [ERROR] Retrying in 1 second.
[2021-04-09 09:26:18 +0000] [2680] [ERROR] Connection in use: ('0.0.0.0', 80)
[2021-04-09 09:26:18 +0000] [2680] [ERROR] Retrying in 1 second.
[2021-04-09 09:26:19 +0000] [2680] [ERROR] Can't connect to ('0.0.0.0', 80)
[2021-04-09 09:26:46,742] ERROR in app: Exception on /track [POST]
Traceback (most recent call last):
  File "/usr/local/lib/python3.6/dist-packages/flask/app.py", line 2447, in wsgi_app
    response = self.full_dispatch_request()
  File "/usr/local/lib/python3.6/dist-packages/flask/app.py", line 1952, in full_dispatch_request
    rv = self.handle_user_exception(e)
  File "/usr/local/lib/python3.6/dist-packages/flask/app.py", line 1821, in handle_user_exception
    reraise(exc_type, exc_value, tb)
  File "/usr/local/lib/python3.6/dist-packages/flask/_compat.py", line 39, in reraise
    raise value
  File "/usr/local/lib/python3.6/dist-packages/flask/app.py", line 1950, in full_dispatch_request
    rv = self.dispatch_request()
  File "/usr/local/lib/python3.6/dist-packages/flask/app.py", line 1936, in dispatch_request
    return self.view_functions[rule.endpoint](**req.view_args)
  File "/home/user/ptz-tracker/flask_server.py", line 41, in tracker_listener
    print("Tracker Successful started on pid: " + str(pid))
OSError: [Errno 5] Input/output error
[2021-04-09 09:27:21,786] ERROR in app: Exception on /track [POST]
Traceback (most recent call last):
  File "/usr/local/lib/python3.6/dist-packages/flask/app.py", line 2447, in wsgi_app
    response = self.full_dispatch_request()
  File "/usr/local/lib/python3.6/dist-packages/flask/app.py", line 1952, in full_dispatch_request
    rv = self.handle_user_exception(e)
  File "/usr/local/lib/python3.6/dist-packages/flask/app.py", line 1821, in handle_user_exception
    reraise(exc_type, exc_value, tb)
  File "/usr/local/lib/python3.6/dist-packages/flask/_compat.py", line 39, in reraise
    raise value
  File "/usr/local/lib/python3.6/dist-packages/flask/app.py", line 1950, in full_dispatch_request
    rv = self.dispatch_request()
  File "/usr/local/lib/python3.6/dist-packages/flask/app.py", line 1936, in dispatch_request
    return self.view_functions[rule.endpoint](**req.view_args)
  File "/home/user/ptz-tracker/flask_server.py", line 41, in tracker_listener
    print("Tracker Successful started on pid: " + str(pid))
OSError: [Errno 5] Input/output error
[2021-04-09 09:29:57 +0000] [2654] [INFO] Parent changed, shutting down: <Worker 2654>
[2021-04-09 09:29:57 +0000] [2654] [INFO] Worker exiting (pid: 2654)
[2021-04-09 09:31:39 +0000] [2724] [INFO] Starting gunicorn 20.1.0
[2021-04-09 09:31:39 +0000] [2724] [INFO] Listening at: http://127.0.0.1:8000 (2724)
[2021-04-09 09:31:39 +0000] [2724] [INFO] Using worker: sync
[2021-04-09 09:31:39 +0000] [2727] [INFO] Booting worker with pid: 2727
[2021-04-09 09:32:10 +0000] [2733] [INFO] Starting gunicorn 20.1.0
[2021-04-09 09:32:10 +0000] [2733] [ERROR] Connection in use: ('127.0.0.1', 8000)
[2021-04-09 09:32:10 +0000] [2733] [ERROR] Retrying in 1 second.
[2021-04-09 09:32:11 +0000] [2733] [ERROR] Connection in use: ('127.0.0.1', 8000)
[2021-04-09 09:32:11 +0000] [2733] [ERROR] Retrying in 1 second.
[2021-04-09 09:32:12 +0000] [2733] [ERROR] Connection in use: ('127.0.0.1', 8000)
[2021-04-09 09:32:12 +0000] [2733] [ERROR] Retrying in 1 second.
[2021-04-09 09:32:13 +0000] [2733] [ERROR] Connection in use: ('127.0.0.1', 8000)
[2021-04-09 09:32:13 +0000] [2733] [ERROR] Retrying in 1 second.
[2021-04-09 09:32:14 +0000] [2733] [ERROR] Connection in use: ('127.0.0.1', 8000)
[2021-04-09 09:32:14 +0000] [2733] [ERROR] Retrying in 1 second.
[2021-04-09 09:32:15 +0000] [2733] [ERROR] Can't connect to ('127.0.0.1', 8000)
[2021-04-09 09:32:40 +0000] [2740] [INFO] Starting gunicorn 20.1.0
[2021-04-09 09:32:40 +0000] [2740] [INFO] Listening at: http://0.0.0.0:80 (2740)
[2021-04-09 09:32:40 +0000] [2740] [INFO] Using worker: sync
[2021-04-09 09:32:40 +0000] [2744] [INFO] Booting worker with pid: 2744
[2021-04-09 09:33:52 +0000] [2727] [INFO] Worker exiting (pid: 2727)
[2021-04-09 09:33:52 +0000] [2744] [INFO] Worker exiting (pid: 2744)
[2021-04-09 09:33:52 +0000] [2740] [INFO] Handling signal: term
[2021-04-09 09:33:52 +0000] [2724] [INFO] Handling signal: term
[2021-04-09 09:33:52 +0000] [2724] [WARNING] Worker with pid 2727 was terminated due to signal 15
[2021-04-09 09:33:52 +0000] [2740] [WARNING] Worker with pid 2744 was terminated due to signal 15
[2021-04-09 09:33:52 +0000] [2740] [INFO] Shutting down: Master
[2021-04-09 09:33:52 +0000] [2724] [INFO] Shutting down: Master
[2021-04-09 09:34:29 +0000] [1407] [INFO] Starting gunicorn 20.1.0
[2021-04-09 09:34:29 +0000] [1407] [INFO] Listening at: http://0.0.0.0:80 (1407)
[2021-04-09 09:34:29 +0000] [1407] [INFO] Using worker: sync
[2021-04-09 09:34:29 +0000] [1411] [INFO] Booting worker with pid: 1411
[2021-04-09 09:37:20 +0000] [1411] [INFO] Worker exiting (pid: 1411)
[2021-04-09 09:37:20 +0000] [1407] [INFO] Handling signal: term
[2021-04-09 09:37:20 +0000] [1407] [INFO] Shutting down: Master
[2021-04-09 09:42:39 +0000] [999] [INFO] Starting gunicorn 20.1.0
[2021-04-09 09:42:39 +0000] [999] [INFO] Listening at: http://0.0.0.0:80 (999)
[2021-04-09 09:42:39 +0000] [999] [INFO] Using worker: sync
[2021-04-09 09:42:39 +0000] [1003] [INFO] Booting worker with pid: 1003
[2021-04-09 09:42:39 +0000] [1003] [ERROR] Exception in worker process
Traceback (most recent call last):
  File "/home/user/.local/lib/python3.6/site-packages/gunicorn/util.py", line 359, in import_app
    mod = importlib.import_module(module)
  File "/usr/lib/python3.6/importlib/__init__.py", line 126, in import_module
    return _bootstrap._gcd_import(name[level:], package, level)
  File "<frozen importlib._bootstrap>", line 994, in _gcd_import
  File "<frozen importlib._bootstrap>", line 971, in _find_and_load
  File "<frozen importlib._bootstrap>", line 950, in _find_and_load_unlocked
ModuleNotFoundError: No module named 'flask_server.py'; 'flask_server' is not a package

During handling of the above exception, another exception occurred:

Traceback (most recent call last):
  File "/home/user/.local/lib/python3.6/site-packages/gunicorn/arbiter.py", line 589, in spawn_worker
    worker.init_process()
  File "/home/user/.local/lib/python3.6/site-packages/gunicorn/workers/base.py", line 134, in init_process
    self.load_wsgi()
  File "/home/user/.local/lib/python3.6/site-packages/gunicorn/workers/base.py", line 146, in load_wsgi
    self.wsgi = self.app.wsgi()
  File "/home/user/.local/lib/python3.6/site-packages/gunicorn/app/base.py", line 67, in wsgi
    self.callable = self.load()
  File "/home/user/.local/lib/python3.6/site-packages/gunicorn/app/wsgiapp.py", line 58, in load
    return self.load_wsgiapp()
  File "/home/user/.local/lib/python3.6/site-packages/gunicorn/app/wsgiapp.py", line 48, in load_wsgiapp
    return util.import_app(self.app_uri)
  File "/home/user/.local/lib/python3.6/site-packages/gunicorn/util.py", line 363, in import_app
    raise ImportError(msg % (module.rsplit(".", 1)[0], obj))
ImportError: Failed to find application, did you mean 'flask_server:app'?
[2021-04-09 09:42:39 +0000] [1003] [INFO] Worker exiting (pid: 1003)
[2021-04-09 09:42:39 +0000] [999] [INFO] Shutting down: Master
[2021-04-09 09:42:39 +0000] [999] [INFO] Reason: Worker failed to boot.
[2021-04-09 09:53:51 +0000] [1040] [INFO] Starting gunicorn 20.1.0
[2021-04-09 09:53:51 +0000] [1040] [INFO] Listening at: http://0.0.0.0:80 (1040)
[2021-04-09 09:53:51 +0000] [1040] [INFO] Using worker: sync
[2021-04-09 09:53:51 +0000] [1044] [INFO] Booting worker with pid: 1044
[2021-04-09 09:54:41 +0000] [1044] [INFO] Worker exiting (pid: 1044)
[2021-04-09 09:54:41 +0000] [1040] [INFO] Handling signal: term
[2021-04-09 09:54:41 +0000] [1040] [WARNING] Worker with pid 1044 was terminated due to signal 15
[2021-04-09 09:54:41 +0000] [1040] [INFO] Shutting down: Master
[2021-04-09 09:55:22 +0000] [919] [INFO] Starting gunicorn 20.1.0
[2021-04-09 09:55:22 +0000] [919] [INFO] Listening at: http://0.0.0.0:80 (919)
[2021-04-09 09:55:22 +0000] [919] [INFO] Using worker: sync
[2021-04-09 09:55:22 +0000] [923] [INFO] Booting worker with pid: 923
[2021-04-09 09:59:11 +0000] [950] [INFO] Starting gunicorn 20.1.0
[2021-04-09 09:59:11 +0000] [950] [ERROR] Connection in use: ('0.0.0.0', 80)
[2021-04-09 09:59:11 +0000] [950] [ERROR] Retrying in 1 second.
[2021-04-09 09:59:12 +0000] [950] [ERROR] Connection in use: ('0.0.0.0', 80)
[2021-04-09 09:59:12 +0000] [950] [ERROR] Retrying in 1 second.
[2021-04-09 09:59:13 +0000] [950] [ERROR] Connection in use: ('0.0.0.0', 80)
[2021-04-09 09:59:13 +0000] [950] [ERROR] Retrying in 1 second.
[2021-04-09 09:59:14 +0000] [950] [ERROR] Connection in use: ('0.0.0.0', 80)
[2021-04-09 09:59:14 +0000] [950] [ERROR] Retrying in 1 second.
[2021-04-09 09:59:15 +0000] [950] [ERROR] Connection in use: ('0.0.0.0', 80)
[2021-04-09 09:59:15 +0000] [950] [ERROR] Retrying in 1 second.
[2021-04-09 09:59:16 +0000] [950] [ERROR] Can't connect to ('0.0.0.0', 80)
[2021-04-09 10:09:02 +0000] [919] [INFO] Handling signal: term
[2021-04-09 10:09:02 +0000] [923] [INFO] Worker exiting (pid: 923)
[2021-04-09 10:09:02 +0000] [919] [INFO] Shutting down: Master
[2021-04-09 10:13:05 +0000] [910] [INFO] Starting gunicorn 20.1.0
[2021-04-09 10:13:05 +0000] [910] [INFO] Listening at: http://0.0.0.0:80 (910)
[2021-04-09 10:13:05 +0000] [910] [INFO] Using worker: sync
[2021-04-09 10:13:05 +0000] [914] [INFO] Booting worker with pid: 914
[2021-04-09 11:31:55 +0000] [1028] [INFO] Starting gunicorn 20.1.0
[2021-04-09 11:31:55 +0000] [1028] [ERROR] Connection in use: ('0.0.0.0', 80)
[2021-04-09 11:31:55 +0000] [1028] [ERROR] Retrying in 1 second.
[2021-04-09 11:31:56 +0000] [1028] [ERROR] Connection in use: ('0.0.0.0', 80)
[2021-04-09 11:31:56 +0000] [1028] [ERROR] Retrying in 1 second.
[2021-04-09 11:31:57 +0000] [1028] [ERROR] Connection in use: ('0.0.0.0', 80)
[2021-04-09 11:31:57 +0000] [1028] [ERROR] Retrying in 1 second.
[2021-04-09 11:31:58 +0000] [1028] [ERROR] Connection in use: ('0.0.0.0', 80)
[2021-04-09 11:31:58 +0000] [1028] [ERROR] Retrying in 1 second.
[2021-04-09 11:31:59 +0000] [1028] [ERROR] Connection in use: ('0.0.0.0', 80)
[2021-04-09 11:31:59 +0000] [1028] [ERROR] Retrying in 1 second.
[2021-04-09 11:32:00 +0000] [1028] [ERROR] Can't connect to ('0.0.0.0', 80)
[2021-04-09 14:07:58 +0000] [1170] [INFO] Starting gunicorn 20.1.0
[2021-04-09 14:07:58 +0000] [1170] [ERROR] Connection in use: ('0.0.0.0', 80)
[2021-04-09 14:07:58 +0000] [1170] [ERROR] Retrying in 1 second.
[2021-04-09 14:07:59 +0000] [1170] [ERROR] Connection in use: ('0.0.0.0', 80)
[2021-04-09 14:07:59 +0000] [1170] [ERROR] Retrying in 1 second.
[2021-04-09 14:08:00 +0000] [1170] [ERROR] Connection in use: ('0.0.0.0', 80)
[2021-04-09 14:08:00 +0000] [1170] [ERROR] Retrying in 1 second.
[2021-04-09 14:08:01 +0000] [1170] [ERROR] Connection in use: ('0.0.0.0', 80)
[2021-04-09 14:08:01 +0000] [1170] [ERROR] Retrying in 1 second.
[2021-04-09 14:08:02 +0000] [1170] [ERROR] Connection in use: ('0.0.0.0', 80)
[2021-04-09 14:08:02 +0000] [1170] [ERROR] Retrying in 1 second.
[2021-04-09 14:08:03 +0000] [1170] [ERROR] Can't connect to ('0.0.0.0', 80)
[2021-04-09 21:05:09 +0000] [910] [INFO] Handling signal: term
[2021-04-09 21:05:09 +0000] [914] [INFO] Worker exiting (pid: 914)
[2021-04-09 21:05:09 +0000] [910] [WARNING] Worker with pid 914 was terminated due to signal 15
[2021-04-09 21:05:09 +0000] [910] [INFO] Shutting down: Master
